<?xml version="1.0" encoding="UTF-8"?>
<!-- Generated by org.testng.reporters.JUnitReportReporter -->
<testsuite hostname="DESKTOP-NNV3G3C" failures="1" tests="11" name="v2api_TestCaseSuit.ApiTest" time="7.319" errors="0" timestamp="29 Jul 2019 13:04:49 GMT" skipped="0">
  <testcase classname="v2api_TestCaseSuit.ApiTest" name="Generate_OTP" time="2.231"/>
  <testcase classname="v2api_TestCaseSuit.ApiTest" name="VerifyOTP" time="0.430"/>
  <testcase classname="v2api_TestCaseSuit.ApiTest" name="GetPin" time="0.360"/>
  <testcase classname="v2api_TestCaseSuit.ApiTest" name="UpdatePin" time="0.230"/>
  <testcase classname="v2api_TestCaseSuit.ApiTest" name="FatchApplicationDetails" time="0.535"/>
  <testcase classname="v2api_TestCaseSuit.ApiTest" name="fatchGioLocation" time="1.553"/>
  <testcase classname="v2api_TestCaseSuit.ApiTest" name="CheckServiceable" time="0.338"/>
  <testcase classname="v2api_TestCaseSuit.ApiTest" name="ValidatePan" time="0.263"/>
  <testcase classname="v2api_TestCaseSuit.ApiTest" name="CreateCustomer" time="0.666"/>
  <testcase classname="v2api_TestCaseSuit.ApiTest" name="LocationUpdate" time="0.329"/>
  <testcase classname="v2api_TestCaseSuit.ApiTest" name="SaveMobileContacts" time="0.384">
    <failure message="
Expected: is &quot;Request Processed Successfully&quot;
     got: &quot;Invalid Encrypted Data&quot;
" type="java.lang.AssertionError">
      <![CDATA[java.lang.AssertionError: 
Expected: is "Request Processed Successfully"
     got: "Invalid Encrypted Data"

at org.junit.Assert.assertThat(Assert.java:780)
at org.junit.Assert.assertThat(Assert.java:738)
at v2api_TestCaseSuit.ApiTest.SaveMobileContacts(ApiTest.java:160)
at java.base/jdk.internal.reflect.NativeMethodAccessorImpl.invoke0(Native Method)
at java.base/jdk.internal.reflect.NativeMethodAccessorImpl.invoke(Unknown Source)
at java.base/jdk.internal.reflect.DelegatingMethodAccessorImpl.invoke(Unknown Source)
at java.base/java.lang.reflect.Method.invoke(Unknown Source)
at org.testng.internal.MethodInvocationHelper.invokeMethod(MethodInvocationHelper.java:124)
at org.testng.internal.Invoker.invokeMethod(Invoker.java:583)
at org.testng.internal.Invoker.invokeTestMethod(Invoker.java:719)
at org.testng.internal.Invoker.invokeTestMethods(Invoker.java:989)
at org.testng.internal.TestMethodWorker.invokeTestMethods(TestMethodWorker.java:125)
at org.testng.internal.TestMethodWorker.run(TestMethodWorker.java:109)
at org.testng.TestRunner.privateRun(TestRunner.java:648)
at org.testng.TestRunner.run(TestRunner.java:505)
at org.testng.SuiteRunner.runTest(SuiteRunner.java:455)
at org.testng.SuiteRunner.runSequentially(SuiteRunner.java:450)
at org.testng.SuiteRunner.privateRun(SuiteRunner.java:415)
at org.testng.SuiteRunner.run(SuiteRunner.java:364)
at org.testng.SuiteRunnerWorker.runSuite(SuiteRunnerWorker.java:52)
at org.testng.SuiteRunnerWorker.run(SuiteRunnerWorker.java:84)
at org.testng.TestNG.runSuitesSequentially(TestNG.java:1208)
at org.testng.TestNG.runSuitesLocally(TestNG.java:1137)
at org.testng.TestNG.runSuites(TestNG.java:1049)
at org.testng.TestNG.run(TestNG.java:1017)
at org.testng.remote.AbstractRemoteTestNG.run(AbstractRemoteTestNG.java:114)
at org.testng.remote.RemoteTestNG.initAndRun(RemoteTestNG.java:251)
at org.testng.remote.RemoteTestNG.main(RemoteTestNG.java:77)
]]>
    </failure>
  </testcase> <!-- SaveMobileContacts -->
</testsuite> <!-- v2api_TestCaseSuit.ApiTest -->
